<mujoco model="A3T2.5_pingpang">
  <compiler angle="radian" meshdir="meshes"/>

  <asset>
    <mesh name="pelvis_link" file="pelvis_link.STL"/>
    <mesh name="waist_yaw_Link" file="waist_yaw_Link.STL"/>
    <mesh name="waist_roll_Link" file="waist_roll_Link.STL"/>
    <mesh name="torso_Link" file="torso_Link.STL"/>
    <mesh name="torso_shell_Link" file="torso_shell_Link.STL"/>
    <mesh name="imu_in_torso_Link" file="imu_in_torso_Link.STL"/>
    <mesh name="head_yaw_Link" file="head_yaw_Link.STL"/>
    <mesh name="head_pitch_Link" file="head_pitch_Link.STL"/>
    <mesh name="std_head_stereo_camera_Link" file="std_head_stereo_camera_Link.STL"/>
    <mesh name="left_shoulder_pitch_Link" file="left_shoulder_pitch_Link.STL"/>
    <mesh name="left_shoulder_roll_Link" file="left_shoulder_roll_Link.STL"/>
    <mesh name="left_shoulder_yaw_Link" file="left_shoulder_yaw_Link.STL"/>
    <mesh name="left_elbow_Link" file="left_elbow_Link.STL"/>
    <mesh name="left_wrist_roll_Link" file="left_wrist_roll_Link.STL"/>
    <mesh name="left_wrist_pitch_Link" file="left_wrist_pitch_Link.STL"/>
    <mesh name="left_wrist_yaw_Link" file="left_wrist_yaw_Link.STL"/>
    <mesh name="left_hand_Link" file="left_hand_Link.STL"/>
    <mesh name="right_shoulder_pitch_Link" file="right_shoulder_pitch_Link.STL"/>
    <mesh name="right_shoulder_roll_Link" file="right_shoulder_roll_Link.STL"/>
    <mesh name="right_shoulder_yaw_Link" file="right_shoulder_yaw_Link.STL"/>
    <mesh name="right_elbow_Link" file="right_elbow_Link.STL"/>
    <mesh name="right_wrist_roll_Link" file="right_wrist_roll_Link.STL"/>
    <mesh name="right_wrist_pitch_Link" file="right_wrist_pitch_Link.STL"/>
    <mesh name="right_wrist_yaw_Link" file="right_wrist_yaw_Link.STL"/>
    <mesh name="right_hand_pingpang_Link" file="right_hand_pingpang_Link.STL"/>
    <mesh name="pingpang_red_Link" file="pingpang_red_Link.STL"/>
    <mesh name="imu_in_pelvis_Link" file="imu_in_pelvis_Link.STL"/>
    <mesh name="left_hip_pitch_Link" file="left_hip_pitch_Link.STL"/>
    <mesh name="left_hip_roll_Link" file="left_hip_roll_Link.STL"/>
    <mesh name="left_hip_yaw_Link" file="left_hip_yaw_Link.STL"/>
    <mesh name="left_knee_Link" file="left_knee_Link.STL"/>
    <mesh name="left_knee_shell_Link" file="left_knee_shell_Link.STL"/>
    <mesh name="left_ankle_pitch_Link" file="left_ankle_pitch_Link.STL"/>
    <mesh name="left_ankle_roll_Link" file="left_ankle_roll_Link.STL"/>
    <mesh name="right_hip_pitch_Link" file="right_hip_pitch_Link.STL"/>
    <mesh name="right_hip_roll_Link" file="right_hip_roll_Link.STL"/>
    <mesh name="right_hip_yaw_Link" file="right_hip_yaw_Link.STL"/>
    <mesh name="right_knee_Link" file="right_knee_Link.STL"/>
    <mesh name="right_knee_shell_Link" file="right_knee_shell_Link.STL"/>
    <mesh name="right_ankle_pitch_Link" file="right_ankle_pitch_Link.STL"/>
    <mesh name="right_ankle_roll_Link" file="right_ankle_roll_Link.STL"/>
  </asset>

  <worldbody>
    <body name="pelvis" pos="0 0 1.02">
      <inertial pos="-0.00090674 2.058e-05 -0.127288" quat="0.999996 0.00180873 -0.00224237 0.000263341" mass="4.86725" diaginertia="0.0219449 0.0175749 0.0134988"/>
      <joint name="floating_base_joint" type="free"/>
      <geom type="mesh" rgba="0.1 0.1 0.1 1" mesh="pelvis_link"/>
      <body name="waist_yaw_link">
        <inertial pos="0.0018168 -0.00204337 -0.0228619" quat="0.056891 0.725998 -0.0393199 0.68421" mass="0.245194" diaginertia="0.000360867 0.000232085 0.000183698"/>
        <joint name="waist_yaw_joint" pos="0 0 0" axis="0 0 1" range="-2.61799 2.61799" actuatorfrcrange="-220 220"/>
        <geom type="mesh" rgba="0.1 0.1 0.1 1" mesh="waist_yaw_Link"/>
        <body name="waist_roll_link">
          <inertial pos="-0.02 0 0.0024982" quat="0 0.707107 0 0.707107" mass="0.135382" diaginertia="4.8e-05 2.953e-05 2.952e-05"/>
          <joint name="waist_roll_joint" pos="0 0 0" axis="1 0 0" range="-0.349066 0.349066" actuatorfrcrange="-46 46"/>
          <geom type="mesh" rgba="0.1 0.1 0.1 1" mesh="waist_roll_Link"/>
          <body name="torso_link" pos="-0.02 0 0.005">
            <inertial pos="0.0151322 -0.0002682 0.198251" quat="0.999601 0.00426384 -0.0223792 -0.0167121" mass="17.5768" diaginertia="0.220485 0.179498 0.120581"/>
            <joint name="waist_pitch_joint" pos="0 0 0" axis="0 1 0" range="-0.488692 0.418879" actuatorfrcrange="-118 118"/>
            <geom type="mesh" rgba="0.1 0.1 0.1 1" mesh="torso_Link"/>
            <body name="torso_shell_link">
              <inertial pos="0 0 0" mass="0" diaginertia="0 0 0"/>
              <geom type="mesh" rgba="1 1 1 1" mesh="torso_shell_Link"/>
            </body>
            <body name="imu_in_torso_link" pos="0 0 0.11185">
              <inertial pos="0.00319251 0.01088 0.00140846" quat="0.5 0.5 -0.5 0.5" mass="0.02" diaginertia="5.27e-06 2.86e-06 2.78e-06"/>
              <geom type="mesh" rgba="0.1 0.1 0.1 1" mesh="imu_in_torso_Link"/>
            </body>
            <body name="head_yaw_link" pos="0.0303 0 0.28896">
              <inertial pos="-0.00051068 -0.00466266 0.173807" quat="0.99646 0.0526635 -0.0362023 0.0546288" mass="0.56546" diaginertia="0.00219578 0.00211246 0.00108933"/>
              <geom type="mesh" rgba="0.1 0.1 0.1 1" mesh="head_yaw_Link"/>
              <body name="head_pitch_link" pos="0 0 0.21904">
                <inertial pos="0.0204937 0.00056856 0.047024" quat="0.973049 -0.0072176 -0.230468 0.00302893" mass="1.5348" diaginertia="0.011829 0.0105356 0.00889493"/>
                <geom type="mesh" rgba="0.1 0.1 0.1 1" mesh="head_pitch_Link"/>
                <body name="std_head_stereo_camera_link" pos="0.0838768 0 -0.0208693" quat="0.996208 0 0.0870047 0">
                  <inertial pos="0 0 0" mass="0" diaginertia="0 0 0"/>
                  <geom type="mesh" rgba="0.1 0.1 0.1 1" mesh="std_head_stereo_camera_Link"/>
                </body>
              </body>
            </body>
            <body name="left_shoulder_pitch_link" pos="0.0303 0.148225 0.283818" quat="0.999048 0.0436194 0 0">
              <inertial pos="0.00096906 0.0547743 0.00016529" quat="0.721275 0.692333 0.0172613 0.0117828" mass="1.01945" diaginertia="0.00117978 0.000989191 0.000956331"/>
              <joint name="left_shoulder_pitch_joint" pos="0 0 0" axis="0 1 0" range="-2.87979 2.87979" actuatorfrcrange="-60 60"/>
              <geom type="mesh" rgba="0.1 0.1 0.1 1" mesh="left_shoulder_pitch_Link"/>
              <body name="left_shoulder_roll_link" pos="0 0.059 0" quat="0.999048 -0.0436194 0 0">
                <inertial pos="5.07e-06 0.00923692 -0.0865874" quat="0.714645 0.0375872 -0.000318489 0.698476" mass="0.890486" diaginertia="0.00254936 0.00226679 0.00114044"/>
                <joint name="left_shoulder_roll_joint" pos="0 0 0" axis="1 0 0" range="-0.0872665 2.61799" actuatorfrcrange="-60 60"/>
                <geom type="mesh" rgba="1 1 1 1" mesh="left_shoulder_roll_Link"/>
                <body name="left_shoulder_yaw_link" pos="0 0.01 -0.1475">
                  <inertial pos="0.00426502 -0.00144977 -0.0890828" quat="0.713571 -0.043208 -0.0266623 0.698741" mass="0.999559" diaginertia="0.00331014 0.00326462 0.000848276"/>
                  <joint name="left_shoulder_yaw_joint" pos="0 0 0" axis="0 0 1" range="-2.79253 2.79253" actuatorfrcrange="-24 24"/>
                  <geom type="mesh" rgba="1 1 1 1" mesh="left_shoulder_yaw_Link"/>
                  <body name="left_elbow_link" pos="0.01 0 -0.1325">
                    <inertial pos="0.0776011 -0.00121006 -0.0104096" quat="-0.0210142 0.709386 0.0505757 0.702689" mass="0.712044" diaginertia="0.00124115 0.00117025 0.000537076"/>
                    <joint name="left_elbow_joint" pos="0 0 0" axis="0 1 0" range="-0.959931 1.74533" actuatorfrcrange="-24 24"/>
                    <geom type="mesh" rgba="1 1 1 1" mesh="left_elbow_Link"/>
                    <body name="left_wrist_roll_link" pos="0.129 0 -0.01">
                      <inertial pos="0.0209014 -0.00032839 1.007e-05" quat="0.286321 0.645908 -0.288116 0.646384" mass="0.19186" diaginertia="0.00019562 0.000163226 0.000151184"/>
                      <joint name="left_wrist_roll_joint" pos="0 0 0" axis="1 0 0" range="-2.79253 2.79253" actuatorfrcrange="-24 24"/>
                      <geom type="mesh" rgba="1 1 1 1" mesh="left_wrist_roll_Link"/>
                      <body name="left_wrist_pitch_link" pos="0.06 0 0">
                        <inertial pos="0.022825 -0.00080274 -0.0007711" quat="0.486247 0.495615 0.521419 0.496037" mass="0.567464" diaginertia="0.000515892 0.000514735 0.000233443"/>
                        <joint name="left_wrist_pitch_joint" pos="0 0 0" axis="0 1 0" range="-1.62316 1.62316" actuatorfrcrange="-6 6"/>
                        <geom type="mesh" rgba="0.1 0.1 0.1 1" mesh="left_wrist_pitch_Link"/>
                        <body name="left_wrist_yaw_link" pos="0.046 0 0">
                          <inertial pos="0.0210166 6.725e-05 -0.00216659" quat="0.703146 0.058038 0.0582409 0.706275" mass="0.0806776" diaginertia="8.86505e-05 6.42879e-05 4.57316e-05"/>
                          <joint name="left_wrist_yaw_joint" pos="0 0 0" axis="0 0 1" range="-1.62316 1.62316" actuatorfrcrange="-6 6"/>
                          <geom type="mesh" rgba="1 1 1 1" mesh="left_wrist_yaw_Link"/>
                          <body name="left_hand_link">
                            <inertial pos="0.110066 -0.00410937 0.0048369" quat="0.398897 0.60179 0.378193 0.579397" mass="0.2" diaginertia="0.000954319 0.000748899 0.000358312"/>
                            <geom type="mesh" rgba="1 1 1 1" mesh="left_hand_Link"/>
                          </body>
                        </body>
                      </body>
                    </body>
                  </body>
                </body>
              </body>
            </body>
            <body name="right_shoulder_pitch_link" pos="0.0303 -0.148225 0.283818" quat="0.999048 -0.0436194 0 0">
              <inertial pos="0.00097159 -0.0547742 0.00018343" quat="0.702891 0.710995 -0.0122886 -0.0167424" mass="1.01942" diaginertia="0.00117971 0.000989006 0.00095622"/>
              <joint name="right_shoulder_pitch_joint" pos="0 0 0" axis="0 1 0" range="-2.87979 2.87979" actuatorfrcrange="-60 60"/>
              <geom type="mesh" rgba="0.1 0.1 0.1 1" mesh="right_shoulder_pitch_Link"/>
              <body name="right_shoulder_roll_link" pos="0 -0.059 0" quat="0.999048 0.0436194 0 0">
                <inertial pos="0.00014979 -0.00929496 -0.0864344" quat="0.702001 -0.000812467 0.0367826 0.711225" mass="0.890169" diaginertia="0.0025451 0.00226208 0.00114163"/>
                <joint name="right_shoulder_roll_joint" pos="0 0 0" axis="1 0 0" range="-2.61799 0.0872665" actuatorfrcrange="-60 60"/>
                <geom type="mesh" rgba="1 1 1 1" mesh="right_shoulder_roll_Link"/>
                <body name="right_shoulder_yaw_link" pos="0 -0.01 -0.1475">
                  <inertial pos="0.00413428 0.00146128 -0.0895327" quat="0.715978 -0.0247346 -0.043496 0.696328" mass="0.998599" diaginertia="0.00332583 0.00327983 0.000848304"/>
                  <joint name="right_shoulder_yaw_joint" pos="0 0 0" axis="0 0 1" range="-2.79253 2.79253" actuatorfrcrange="-24 24"/>
                  <geom type="mesh" rgba="1 1 1 1" mesh="right_shoulder_yaw_Link"/>
                  <body name="right_elbow_link" pos="0.01 0 -0.133">
                    <inertial pos="0.0776546 0.00122539 -0.0103208" quat="0.0156278 0.711467 -0.0557273 0.700332" mass="0.711878" diaginertia="0.00123618 0.00116622 0.000538053"/>
                    <joint name="right_elbow_joint" pos="0 0 0" axis="0 1 0" range="-0.959931 1.74533" actuatorfrcrange="-24 24"/>
                    <geom type="mesh" rgba="1 1 1 1" mesh="right_elbow_Link"/>
                    <body name="right_wrist_roll_link" pos="0.129 0 -0.01">
                      <inertial pos="0.0209014 0.00032839 -1.007e-05" quat="0.646384 0.288116 -0.645908 0.286321" mass="0.19186" diaginertia="0.00019562 0.000163226 0.000151184"/>
                      <joint name="right_wrist_roll_joint" pos="0 0 0" axis="1 0 0" range="-2.79253 2.79253" actuatorfrcrange="-24 24"/>
                      <geom type="mesh" rgba="1 1 1 1" mesh="right_wrist_roll_Link"/>
                      <body name="right_wrist_pitch_link" pos="0.06 0 0">
                        <inertial pos="0.022825 0.00080274 0.0007711" quat="0.521419 0.496037 0.486247 0.495615" mass="0.567464" diaginertia="0.000515892 0.000514735 0.000233443"/>
                        <joint name="right_wrist_pitch_joint" pos="0 0 0" axis="0 1 0" range="-1.62316 1.62316" actuatorfrcrange="-6 6"/>
                        <geom type="mesh" rgba="0.1 0.1 0.1 1" mesh="right_wrist_pitch_Link"/>
                        <body name="right_wrist_yaw_link" pos="0.046 0 0">
                          <inertial pos="0.0210166 -6.725e-05 0.00216659" quat="0.706275 -0.0582409 -0.058038 0.703146" mass="0.0806776" diaginertia="8.86505e-05 6.42879e-05 4.57316e-05"/>
                          <joint name="right_wrist_yaw_joint" pos="0 0 0" axis="0 0 1" range="-1.62316 1.62316" actuatorfrcrange="-6 6"/>
                          <geom type="mesh" rgba="1 1 1 1" mesh="right_wrist_yaw_Link"/>
                          <body name="right_hand_pingpang_link">
                            <inertial pos="0.138464 0.0151725 -0.0198887" quat="0.566536 0.319346 0.353256 0.672507" mass="0.496621" diaginertia="0.00307661 0.00247657 0.000827554"/>
                            <geom type="mesh" rgba="1 1 1 1" mesh="right_hand_pingpang_Link"/>
                            <body name="pingpang_red_link" pos="0.21021 0.032078 0.032036">
                              <inertial pos="0 0 0" mass="0" diaginertia="0 0 0"/>
                              <geom type="mesh" rgba="1 0 0 1" mesh="pingpang_red_Link"/>
                            </body>
                          </body>
                        </body>
                      </body>
                    </body>
                  </body>
                </body>
              </body>
            </body>
          </body>
        </body>
      </body>
      <body name="imu_in_pelvis_link" pos="0.00437 0 -0.21165">
        <inertial pos="-0.00319251 0.01088 -0.00140846" quat="0.5 0.5 -0.5 0.5" mass="0.02" diaginertia="5.27e-06 2.86e-06 2.78e-06"/>
        <geom type="mesh" rgba="0.1 0.1 0.1 1" mesh="imu_in_pelvis_Link"/>
      </body>
      <body name="left_hip_pitch_link" pos="0 0.122983 -0.178753" quat="0.991445 -0.130526 0 0">
        <inertial pos="0.00721133 0.00458584 -0.0364447" quat="0.955376 0.291453 -0.029975 -0.0376015" mass="1.87346" diaginertia="0.00360407 0.00305967 0.0020625"/>
        <joint name="left_hip_pitch_joint" pos="0 0 0" axis="0 1 0" range="-2.51327 2.93215" actuatorfrcrange="-220 220"/>
        <geom type="mesh" rgba="0.1 0.1 0.1 1" mesh="left_hip_pitch_Link"/>
        <body name="left_hip_roll_link" pos="0 0.0113163 -0.042233" quat="0.991445 0.130526 0 0">
          <inertial pos="-0.00491752 0.00270388 -0.029806" quat="0.505262 0.485974 0.488526 0.519502" mass="0.74493" diaginertia="0.00258919 0.00219627 0.00173352"/>
          <joint name="left_hip_roll_joint" pos="0 0 0" axis="1 0 0" range="-0.523599 1.6057" actuatorfrcrange="-220 220"/>
          <geom type="mesh" rgba="1 1 1 1" mesh="left_hip_roll_Link"/>
          <body name="left_hip_yaw_link">
            <inertial pos="0.00514402 -0.00057695 -0.175518" quat="0.998587 -0.0068251 -0.0293093 -0.0438022" mass="2.64563" diaginertia="0.0304781 0.0300243 0.00574584"/>
            <joint name="left_hip_yaw_joint" pos="0 0 0" axis="0 0 1" range="-2.72271 2.72271" actuatorfrcrange="-220 220"/>
            <geom type="mesh" rgba="1 1 1 1" mesh="left_hip_yaw_Link"/>
            <body name="left_knee_link" pos="0 0 -0.37">
              <inertial pos="0.00089998 -0.0008566 -0.116035" quat="0.674731 0.0135554 0.00734208 0.737903" mass="5.61676" diaginertia="0.0887092 0.0870746 0.00794668"/>
              <joint name="left_knee_joint" pos="0 0 0" axis="0 1 0" range="-0.122173 2.49582" actuatorfrcrange="-320 320"/>
              <geom type="mesh" rgba="1 1 1 1" mesh="left_knee_Link"/>
              <body name="left_knee_shell_link">
                <inertial pos="0 0 0" mass="0" diaginertia="0 0 0"/>
                <geom type="mesh" rgba="0.1 0.1 0.1 1" mesh="left_knee_shell_Link"/>
              </body>
              <body name="left_ankle_pitch_link" pos="0 0 -0.415">
                <inertial pos="0.00315163 0 0.00019267" quat="0.501079 0.501079 -0.498918 0.498918" mass="0.101008" diaginertia="3.69603e-05 2.30797e-05 1.751e-05"/>
                <joint name="left_ankle_pitch_joint" pos="0 0 0" axis="0 1 0" range="-0.907571 0.523599" actuatorfrcrange="-118.2 118.2"/>
                <geom type="mesh" rgba="1 1 1 1" mesh="left_ankle_pitch_Link"/>
                <body name="left_ankle_roll_link">
                  <inertial pos="0.0282287 0 -0.0485267" quat="-1.95727e-05 0.737287 -7.7642e-06 0.67558" mass="0.82545" diaginertia="0.00418238 0.00404434 0.00079071"/>
                  <joint name="left_ankle_roll_joint" pos="0 0 0" axis="1 0 0" range="-0.349066 0.349066" actuatorfrcrange="-54.75 54.75"/>
                  <geom type="mesh" rgba="1 1 1 1" mesh="left_ankle_roll_Link"/>
                </body>
              </body>
            </body>
          </body>
        </body>
      </body>
      <body name="right_hip_pitch_link" pos="0 -0.122983 -0.178753" quat="0.991445 0.130526 0 0">
        <inertial pos="0.00721166 -0.00459403 -0.0364441" quat="0.9553 -0.291636 -0.029918 0.0381367" mass="1.87346" diaginertia="0.0036045 0.00306023 0.00206222"/>
        <joint name="right_hip_pitch_joint" pos="0 0 0" axis="0 1 0" range="-2.51327 2.93215" actuatorfrcrange="-220 220"/>
        <geom type="mesh" rgba="0.1 0.1 0.1 1" mesh="right_hip_pitch_Link"/>
        <body name="right_hip_roll_link" pos="-0.0011 -0.011316 -0.042233" quat="0.991445 -0.130526 0 0">
          <inertial pos="-0.00490292 -0.00270519 -0.0298049" quat="0.519314 0.488716 0.486197 0.505056" mass="0.744914" diaginertia="0.00258927 0.0021963 0.0017335"/>
          <joint name="right_hip_roll_joint" pos="0 0 0" axis="1 0 0" range="-1.6057 0.523599" actuatorfrcrange="-220 220"/>
          <geom type="mesh" rgba="1 1 1 1" mesh="right_hip_roll_Link"/>
          <body name="right_hip_yaw_link">
            <inertial pos="0.00514477 0.00058875 -0.175434" quat="0.998764 0.00685475 -0.029176 0.0396637" mass="2.64888" diaginertia="0.0304909 0.0300338 0.00575075"/>
            <joint name="right_hip_yaw_joint" pos="0 0 0" axis="0 0 1" range="-2.72271 2.72271" actuatorfrcrange="-220 220"/>
            <geom type="mesh" rgba="1 1 1 1" mesh="right_hip_yaw_Link"/>
            <body name="right_knee_link" pos="0 0 -0.37">
              <inertial pos="0.00135435 0.00032516 -0.117896" quat="0.711055 0.00357072 0.0146974 0.702973" mass="5.61676" diaginertia="0.0931634 0.0916264 0.00776674"/>
              <joint name="right_knee_joint" pos="0 0 0" axis="0 1 0" range="-0.122173 2.49582" actuatorfrcrange="-320 320"/>
              <geom type="mesh" rgba="1 1 1 1" mesh="right_knee_Link"/>
              <body name="right_knee_shell_link">
                <inertial pos="0 0 0" mass="0" diaginertia="0 0 0"/>
                <geom type="mesh" rgba="0.1 0.1 0.1 1" mesh="right_knee_shell_Link"/>
              </body>
              <body name="right_ankle_pitch_link" pos="0 0 -0.415">
                <inertial pos="0.00315163 0 0.00019267" quat="0.501079 0.501079 -0.498918 0.498918" mass="0.101008" diaginertia="3.69603e-05 2.30797e-05 1.751e-05"/>
                <joint name="right_ankle_pitch_joint" pos="0 0 0" axis="0 1 0" range="-0.907571 0.523599" actuatorfrcrange="-118.2 118.2"/>
                <geom type="mesh" rgba="1 1 1 1" mesh="right_ankle_pitch_Link"/>
                <body name="right_ankle_roll_link">
                  <inertial pos="0.0282287 1.2e-06 -0.0485259" quat="-4.38594e-05 0.737287 -3.44675e-05 0.67558" mass="0.82545" diaginertia="0.0041824 0.00404439 0.00079077"/>
                  <joint name="right_ankle_roll_joint" pos="0 0 0" axis="1 0 0" range="-0.349066 0.349066" actuatorfrcrange="-54.75 54.75"/>
                  <geom type="mesh" rgba="1 1 1 1" mesh="right_ankle_roll_Link"/>
                </body>
              </body>
            </body>
          </body>
        </body>
      </body>
    </body>
  </worldbody>

  <actuator>
    <general name="waist_yaw_joint" joint="waist_yaw_joint" ctrllimited="true" ctrlrange="-220 220" forcelimited="true" forcerange="-220 220"/>
    <general name="waist_roll_joint" joint="waist_roll_joint" ctrllimited="true" ctrlrange="-46 46" forcelimited="true" forcerange="-46 46"/>
    <general name="waist_pitch_joint" joint="waist_pitch_joint" ctrllimited="true" ctrlrange="-118 118" forcelimited="true" forcerange="-118 118"/>
    <general name="left_shoulder_pitch_joint" joint="left_shoulder_pitch_joint" ctrllimited="true" ctrlrange="-60 60" forcelimited="true" forcerange="-60 60"/>
    <general name="left_shoulder_roll_joint" joint="left_shoulder_roll_joint" ctrllimited="true" ctrlrange="-60 60" forcelimited="true" forcerange="-60 60"/>
    <general name="left_shoulder_yaw_joint" joint="left_shoulder_yaw_joint" ctrllimited="true" ctrlrange="-24 24" forcelimited="true" forcerange="-24 24"/>
    <general name="left_elbow_joint" joint="left_elbow_joint" ctrllimited="true" ctrlrange="-24 24" forcelimited="true" forcerange="-24 24"/>
    <general name="left_wrist_roll_joint" joint="left_wrist_roll_joint" ctrllimited="true" ctrlrange="-24 24" forcelimited="true" forcerange="-24 24"/>
    <general name="left_wrist_pitch_joint" joint="left_wrist_pitch_joint" ctrllimited="true" ctrlrange="-6 6" forcelimited="true" forcerange="-6 6"/>
    <general name="left_wrist_yaw_joint" joint="left_wrist_yaw_joint" ctrllimited="true" ctrlrange="-6 6" forcelimited="true" forcerange="-6 6"/>
    <general name="right_shoulder_pitch_joint" joint="right_shoulder_pitch_joint" ctrllimited="true" ctrlrange="-60 60" forcelimited="true" forcerange="-60 60"/>
    <general name="right_shoulder_roll_joint" joint="right_shoulder_roll_joint" ctrllimited="true" ctrlrange="-60 60" forcelimited="true" forcerange="-60 60"/>
    <general name="right_shoulder_yaw_joint" joint="right_shoulder_yaw_joint" ctrllimited="true" ctrlrange="-24 24" forcelimited="true" forcerange="-24 24"/>
    <general name="right_elbow_joint" joint="right_elbow_joint" ctrllimited="true" ctrlrange="-24 24" forcelimited="true" forcerange="-24 24"/>
    <general name="right_wrist_roll_joint" joint="right_wrist_roll_joint" ctrllimited="true" ctrlrange="-24 24" forcelimited="true" forcerange="-24 24"/>
    <general name="right_wrist_pitch_joint" joint="right_wrist_pitch_joint" ctrllimited="true" ctrlrange="-6 6" forcelimited="true" forcerange="-6 6"/>
    <general name="right_wrist_yaw_joint" joint="right_wrist_yaw_joint" ctrllimited="true" ctrlrange="-6 6" forcelimited="true" forcerange="-6 6"/>
    <general name="left_hip_pitch_joint" joint="left_hip_pitch_joint" ctrllimited="true" ctrlrange="-220 220" forcelimited="true" forcerange="-220 220"/>
    <general name="left_hip_roll_joint" joint="left_hip_roll_joint" ctrllimited="true" ctrlrange="-220 220" forcelimited="true" forcerange="-220 220"/>
    <general name="left_hip_yaw_joint" joint="left_hip_yaw_joint" ctrllimited="true" ctrlrange="-220 220" forcelimited="true" forcerange="-220 220"/>
    <general name="left_knee_joint" joint="left_knee_joint" ctrllimited="true" ctrlrange="-320 320" forcelimited="true" forcerange="-320 320"/>
    <general name="left_ankle_pitch_joint" joint="left_ankle_pitch_joint" ctrllimited="true" ctrlrange="-118.2 118.2" forcelimited="true" forcerange="-118.2 118.2"/>
    <general name="left_ankle_roll_joint" joint="left_ankle_roll_joint" ctrllimited="true" ctrlrange="-54.75 54.75" forcelimited="true" forcerange="-54.75 54.75"/>
    <general name="right_hip_pitch_joint" joint="right_hip_pitch_joint" ctrllimited="true" ctrlrange="-220 220" forcelimited="true" forcerange="-220 220"/>
    <general name="right_hip_roll_joint" joint="right_hip_roll_joint" ctrllimited="true" ctrlrange="-220 220" forcelimited="true" forcerange="-220 220"/>
    <general name="right_hip_yaw_joint" joint="right_hip_yaw_joint" ctrllimited="true" ctrlrange="-220 220" forcelimited="true" forcerange="-220 220"/>
    <general name="right_knee_joint" joint="right_knee_joint" ctrllimited="true" ctrlrange="-320 320" forcelimited="true" forcerange="-320 320"/>
    <general name="right_ankle_pitch_joint" joint="right_ankle_pitch_joint" ctrllimited="true" ctrlrange="-118.2 118.2" forcelimited="true" forcerange="-118.2 118.2"/>
    <general name="right_ankle_roll_joint" joint="right_ankle_roll_joint" ctrllimited="true" ctrlrange="-54.75 54.75" forcelimited="true" forcerange="-54.75 54.75"/>
  </actuator>
</mujoco>
